[35mDEBUG   [0m selenium.webdriver.common.selenium_manager:selenium_manager.py:101 Selenium Manager binary found at: /Users/sumit/PycharmProjects/PartnerPortalUI/.venv/lib/python3.9/site-packages/selenium/webdriver/common/macos/selenium-manager
[35mDEBUG   [0m selenium.webdriver.common.selenium_manager:selenium_manager.py:114 Executing process: /Users/sumit/PycharmProjects/PartnerPortalUI/.venv/lib/python3.9/site-packages/selenium/webdriver/common/macos/selenium-manager --browser chrome --debug --language-binding python --output json
[35mDEBUG   [0m selenium.webdriver.common.selenium_manager:selenium_manager.py:140 Sending stats to Plausible: Props { browser: "chrome", browser_version: "", os: "macos", arch: "arm64", lang: "python", selenium_version: "4.32" }
[35mDEBUG   [0m selenium.webdriver.common.selenium_manager:selenium_manager.py:140 chromedriver not found in PATH
[35mDEBUG   [0m selenium.webdriver.common.selenium_manager:selenium_manager.py:140 chrome detected at /Applications/Google Chrome.app/Contents/MacOS/Google Chrome
[35mDEBUG   [0m selenium.webdriver.common.selenium_manager:selenium_manager.py:140 Running command: /Applications/Google\ Chrome.app/Contents/MacOS/Google\ Chrome --version
[35mDEBUG   [0m selenium.webdriver.common.selenium_manager:selenium_manager.py:140 Output: "Google Chrome 136.0.7103.114 "
[35mDEBUG   [0m selenium.webdriver.common.selenium_manager:selenium_manager.py:140 Detected browser: chrome 136.0.7103.114
[35mDEBUG   [0m selenium.webdriver.common.selenium_manager:selenium_manager.py:140 Discovering versions from https://googlechromelabs.github.io/chrome-for-testing/known-good-versions-with-downloads.json
[35mDEBUG   [0m selenium.webdriver.common.selenium_manager:selenium_manager.py:140 Required driver: chromedriver 136.0.7103.94
[35mDEBUG   [0m selenium.webdriver.common.selenium_manager:selenium_manager.py:140 chromedriver 136.0.7103.94 already in the cache
[35mDEBUG   [0m selenium.webdriver.common.selenium_manager:selenium_manager.py:140 Driver path: /Users/sumit/.cache/selenium/chromedriver/mac-arm64/136.0.7103.94/chromedriver
[35mDEBUG   [0m selenium.webdriver.common.selenium_manager:selenium_manager.py:140 Browser path: /Applications/Google Chrome.app/Contents/MacOS/Google Chrome
[35mDEBUG   [0m selenium.webdriver.common.service:service.py:231 Started executable: `/Users/sumit/.cache/selenium/chromedriver/mac-arm64/136.0.7103.94/chromedriver` in a child process with pid: 79413 using 0 to output -3
[35mDEBUG   [0m selenium.webdriver.remote.remote_connection:remote_connection.py:403 POST http://localhost:52488/session {'capabilities': {'firstMatch': [{}], 'alwaysMatch': {'browserName': 'chrome', 'pageLoadStrategy': <PageLoadStrategy.normal: 'normal'>, 'browserVersion': None, 'goog:chromeOptions': {'extensions': [], 'binary': '/Applications/Google Chrome.app/Contents/MacOS/Google Chrome', 'args': ['--start-maximized', '--disable-notifications']}}}}
[35mDEBUG   [0m urllib3.connectionpool:connectionpool.py:241 Starting new HTTP connection (1): localhost:52488
[35mDEBUG   [0m urllib3.connectionpool:connectionpool.py:544 http://localhost:52488 "POST /session HTTP/1.1" 200 0
[35mDEBUG   [0m selenium.webdriver.remote.remote_connection:remote_connection.py:436 Remote response: status=200 | data={"value":{"capabilities":{"acceptInsecureCerts":false,"browserName":"chrome","browserVersion":"136.0.7103.114","chrome":{"chromedriverVersion":"136.0.7103.94 (fa0be0b33debeb378a8e6ad9c599be34e2dc3b37-refs/branch-heads/7103@{#1842})","userDataDir":"/var/folders/tf/qc7qzl6x29gdc6yq7s8dn5f80000gp/T/.org.chromium.Chromium.CwV5nA"},"fedcm:accounts":true,"goog:chromeOptions":{"debuggerAddress":"localhost:52497"},"networkConnectionEnabled":false,"pageLoadStrategy":"normal","platformName":"mac","proxy":{},"setWindowRect":true,"strictFileInteractability":false,"timeouts":{"implicit":0,"pageLoad":300000,"script":30000},"unhandledPromptBehavior":"dismiss and notify","webauthn:extension:credBlob":true,"webauthn:extension:largeBlob":true,"webauthn:extension:minPinLength":true,"webauthn:extension:prf":true,"webauthn:virtualAuthenticators":true},"sessionId":"96427ac3a0803f6a9094ca74a6695fd7"}} | headers=HTTPHeaderDict({'Content-Length': '891', 'Content-Type': 'application/json; charset=utf-8', 'cache-control': 'no-cache'})
[35mDEBUG   [0m selenium.webdriver.remote.remote_connection:remote_connection.py:465 Finished Request
[35mDEBUG   [0m selenium.webdriver.remote.remote_connection:remote_connection.py:403 POST http://localhost:52488/session/96427ac3a0803f6a9094ca74a6695fd7/timeouts {'implicit': 10000}
[35mDEBUG   [0m urllib3.connectionpool:connectionpool.py:544 http://localhost:52488 "POST /session/96427ac3a0803f6a9094ca74a6695fd7/timeouts HTTP/1.1" 200 0
[35mDEBUG   [0m selenium.webdriver.remote.remote_connection:remote_connection.py:436 Remote response: status=200 | data={"value":null} | headers=HTTPHeaderDict({'Content-Length': '14', 'Content-Type': 'application/json; charset=utf-8', 'cache-control': 'no-cache'})
[35mDEBUG   [0m selenium.webdriver.remote.remote_connection:remote_connection.py:465 Finished Request
[35mDEBUG   [0m selenium.webdriver.remote.remote_connection:remote_connection.py:403 POST http://localhost:52488/session/96427ac3a0803f6a9094ca74a6695fd7/url {'url': 'https://myyatra.finkraft.ai/auth/signin'}
[35mDEBUG   [0m urllib3.connectionpool:connectionpool.py:544 http://localhost:52488 "POST /session/96427ac3a0803f6a9094ca74a6695fd7/url HTTP/1.1" 200 0
[35mDEBUG   [0m selenium.webdriver.remote.remote_connection:remote_connection.py:436 Remote response: status=200 | data={"value":null} | headers=HTTPHeaderDict({'Content-Length': '14', 'Content-Type': 'application/json; charset=utf-8', 'cache-control': 'no-cache'})
[35mDEBUG   [0m selenium.webdriver.remote.remote_connection:remote_connection.py:465 Finished Request
[35mDEBUG   [0m selenium.webdriver.remote.remote_connection:remote_connection.py:403 POST http://localhost:52488/session/96427ac3a0803f6a9094ca74a6695fd7/window/maximize {}
[35mDEBUG   [0m urllib3.connectionpool:connectionpool.py:544 http://localhost:52488 "POST /session/96427ac3a0803f6a9094ca74a6695fd7/window/maximize HTTP/1.1" 200 0
[35mDEBUG   [0m selenium.webdriver.remote.remote_connection:remote_connection.py:436 Remote response: status=200 | data={"value":{"height":884,"width":1512,"x":0,"y":38}} | headers=HTTPHeaderDict({'Content-Length': '50', 'Content-Type': 'application/json; charset=utf-8', 'cache-control': 'no-cache'})
[35mDEBUG   [0m selenium.webdriver.remote.remote_connection:remote_connection.py:465 Finished Request
[35mDEBUG   [0m selenium.webdriver.remote.remote_connection:remote_connection.py:403 POST http://localhost:52488/session/96427ac3a0803f6a9094ca74a6695fd7/element {'using': 'css selector', 'value': '[id="username"]'}
[35mDEBUG   [0m selenium.webdriver.remote.remote_connection:remote_connection.py:403 DELETE http://localhost:52488/session/96427ac3a0803f6a9094ca74a6695fd7 {}
[35mDEBUG   [0m urllib3.connectionpool:connectionpool.py:241 Starting new HTTP connection (2): localhost:52488
[35mDEBUG   [0m urllib3.util.retry:retry.py:521 Incremented Retry for (url='/session/96427ac3a0803f6a9094ca74a6695fd7'): Retry(total=2, connect=None, read=None, redirect=None, status=None)
[33mWARNING [0m urllib3.connectionpool:connectionpool.py:868 Retrying (Retry(total=2, connect=None, read=None, redirect=None, status=None)) after connection broken by 'NewConnectionError('<urllib3.connection.HTTPConnection object at 0x10494a790>: Failed to establish a new connection: [Errno 61] Connection refused')': /session/96427ac3a0803f6a9094ca74a6695fd7
[35mDEBUG   [0m urllib3.connectionpool:connectionpool.py:241 Starting new HTTP connection (3): localhost:52488
[35mDEBUG   [0m urllib3.util.retry:retry.py:521 Incremented Retry for (url='/session/96427ac3a0803f6a9094ca74a6695fd7'): Retry(total=1, connect=None, read=None, redirect=None, status=None)
[33mWARNING [0m urllib3.connectionpool:connectionpool.py:868 Retrying (Retry(total=1, connect=None, read=None, redirect=None, status=None)) after connection broken by 'NewConnectionError('<urllib3.connection.HTTPConnection object at 0x10494a5b0>: Failed to establish a new connection: [Errno 61] Connection refused')': /session/96427ac3a0803f6a9094ca74a6695fd7
[35mDEBUG   [0m urllib3.connectionpool:connectionpool.py:241 Starting new HTTP connection (4): localhost:52488
[35mDEBUG   [0m urllib3.util.retry:retry.py:521 Incremented Retry for (url='/session/96427ac3a0803f6a9094ca74a6695fd7'): Retry(total=0, connect=None, read=None, redirect=None, status=None)
[33mWARNING [0m urllib3.connectionpool:connectionpool.py:868 Retrying (Retry(total=0, connect=None, read=None, redirect=None, status=None)) after connection broken by 'NewConnectionError('<urllib3.connection.HTTPConnection object at 0x10494a160>: Failed to establish a new connection: [Errno 61] Connection refused')': /session/96427ac3a0803f6a9094ca74a6695fd7
[35mDEBUG   [0m urllib3.connectionpool:connectionpool.py:241 Starting new HTTP connection (5): localhost:52488
[35mDEBUG   [0m selenium.webdriver.common.selenium_manager:selenium_manager.py:101 Selenium Manager binary found at: /Users/sumit/PycharmProjects/PartnerPortalUI/.venv/lib/python3.9/site-packages/selenium/webdriver/common/macos/selenium-manager
[35mDEBUG   [0m selenium.webdriver.common.selenium_manager:selenium_manager.py:114 Executing process: /Users/sumit/PycharmProjects/PartnerPortalUI/.venv/lib/python3.9/site-packages/selenium/webdriver/common/macos/selenium-manager --browser chrome --debug --language-binding python --output json
[35mDEBUG   [0m selenium.webdriver.common.selenium_manager:selenium_manager.py:140 chromedriver not found in PATH
[35mDEBUG   [0m selenium.webdriver.common.selenium_manager:selenium_manager.py:140 chrome detected at /Applications/Google Chrome.app/Contents/MacOS/Google Chrome
[35mDEBUG   [0m selenium.webdriver.common.selenium_manager:selenium_manager.py:140 Running command: /Applications/Google\ Chrome.app/Contents/MacOS/Google\ Chrome --version
[35mDEBUG   [0m selenium.webdriver.common.selenium_manager:selenium_manager.py:140 Output: "Google Chrome 136.0.7103.114 "
[35mDEBUG   [0m selenium.webdriver.common.selenium_manager:selenium_manager.py:140 Detected browser: chrome 136.0.7103.114
[35mDEBUG   [0m selenium.webdriver.common.selenium_manager:selenium_manager.py:140 Required driver: chromedriver 136.0.7103.94
[35mDEBUG   [0m selenium.webdriver.common.selenium_manager:selenium_manager.py:140 chromedriver 136.0.7103.94 already in the cache
[35mDEBUG   [0m selenium.webdriver.common.selenium_manager:selenium_manager.py:140 Driver path: /Users/sumit/.cache/selenium/chromedriver/mac-arm64/136.0.7103.94/chromedriver
[35mDEBUG   [0m selenium.webdriver.common.selenium_manager:selenium_manager.py:140 Browser path: /Applications/Google Chrome.app/Contents/MacOS/Google Chrome
[35mDEBUG   [0m selenium.webdriver.common.service:service.py:231 Started executable: `/Users/sumit/.cache/selenium/chromedriver/mac-arm64/136.0.7103.94/chromedriver` in a child process with pid: 79499 using 0 to output -3
[35mDEBUG   [0m selenium.webdriver.remote.remote_connection:remote_connection.py:403 POST http://localhost:52544/session {'capabilities': {'firstMatch': [{}], 'alwaysMatch': {'browserName': 'chrome', 'pageLoadStrategy': <PageLoadStrategy.normal: 'normal'>, 'browserVersion': None, 'goog:chromeOptions': {'extensions': [], 'binary': '/Applications/Google Chrome.app/Contents/MacOS/Google Chrome', 'args': ['--start-maximized', '--disable-notifications']}}}}
[35mDEBUG   [0m urllib3.connectionpool:connectionpool.py:241 Starting new HTTP connection (1): localhost:52544
[35mDEBUG   [0m urllib3.connectionpool:connectionpool.py:544 http://localhost:52544 "POST /session HTTP/1.1" 200 0
[35mDEBUG   [0m selenium.webdriver.remote.remote_connection:remote_connection.py:436 Remote response: status=200 | data={"value":{"capabilities":{"acceptInsecureCerts":false,"browserName":"chrome","browserVersion":"136.0.7103.114","chrome":{"chromedriverVersion":"136.0.7103.94 (fa0be0b33debeb378a8e6ad9c599be34e2dc3b37-refs/branch-heads/7103@{#1842})","userDataDir":"/var/folders/tf/qc7qzl6x29gdc6yq7s8dn5f80000gp/T/.org.chromium.Chromium.N02rfq"},"fedcm:accounts":true,"goog:chromeOptions":{"debuggerAddress":"localhost:52551"},"networkConnectionEnabled":false,"pageLoadStrategy":"normal","platformName":"mac","proxy":{},"setWindowRect":true,"strictFileInteractability":false,"timeouts":{"implicit":0,"pageLoad":300000,"script":30000},"unhandledPromptBehavior":"dismiss and notify","webauthn:extension:credBlob":true,"webauthn:extension:largeBlob":true,"webauthn:extension:minPinLength":true,"webauthn:extension:prf":true,"webauthn:virtualAuthenticators":true},"sessionId":"43ca733a003044f6e3ca34ad10d9396d"}} | headers=HTTPHeaderDict({'Content-Length': '891', 'Content-Type': 'application/json; charset=utf-8', 'cache-control': 'no-cache'})
[35mDEBUG   [0m selenium.webdriver.remote.remote_connection:remote_connection.py:465 Finished Request
[35mDEBUG   [0m selenium.webdriver.remote.remote_connection:remote_connection.py:403 POST http://localhost:52544/session/43ca733a003044f6e3ca34ad10d9396d/timeouts {'implicit': 10000}
[35mDEBUG   [0m urllib3.connectionpool:connectionpool.py:544 http://localhost:52544 "POST /session/43ca733a003044f6e3ca34ad10d9396d/timeouts HTTP/1.1" 200 0
[35mDEBUG   [0m selenium.webdriver.remote.remote_connection:remote_connection.py:436 Remote response: status=200 | data={"value":null} | headers=HTTPHeaderDict({'Content-Length': '14', 'Content-Type': 'application/json; charset=utf-8', 'cache-control': 'no-cache'})
[35mDEBUG   [0m selenium.webdriver.remote.remote_connection:remote_connection.py:465 Finished Request
[35mDEBUG   [0m selenium.webdriver.remote.remote_connection:remote_connection.py:403 POST http://localhost:52544/session/43ca733a003044f6e3ca34ad10d9396d/url {'url': 'https://myyatra.finkraft.ai/auth/signin'}
[35mDEBUG   [0m urllib3.connectionpool:connectionpool.py:544 http://localhost:52544 "POST /session/43ca733a003044f6e3ca34ad10d9396d/url HTTP/1.1" 200 0
[35mDEBUG   [0m selenium.webdriver.remote.remote_connection:remote_connection.py:436 Remote response: status=200 | data={"value":null} | headers=HTTPHeaderDict({'Content-Length': '14', 'Content-Type': 'application/json; charset=utf-8', 'cache-control': 'no-cache'})
[35mDEBUG   [0m selenium.webdriver.remote.remote_connection:remote_connection.py:465 Finished Request
[35mDEBUG   [0m selenium.webdriver.remote.remote_connection:remote_connection.py:403 POST http://localhost:52544/session/43ca733a003044f6e3ca34ad10d9396d/window/maximize {}
[35mDEBUG   [0m urllib3.connectionpool:connectionpool.py:544 http://localhost:52544 "POST /session/43ca733a003044f6e3ca34ad10d9396d/window/maximize HTTP/1.1" 200 0
[35mDEBUG   [0m selenium.webdriver.remote.remote_connection:remote_connection.py:436 Remote response: status=200 | data={"value":{"height":885,"width":1512,"x":0,"y":38}} | headers=HTTPHeaderDict({'Content-Length': '50', 'Content-Type': 'application/json; charset=utf-8', 'cache-control': 'no-cache'})
[35mDEBUG   [0m selenium.webdriver.remote.remote_connection:remote_connection.py:465 Finished Request
[35mDEBUG   [0m selenium.webdriver.remote.remote_connection:remote_connection.py:403 POST http://localhost:52544/session/43ca733a003044f6e3ca34ad10d9396d/element {'using': 'css selector', 'value': '[id="username"]'}
[35mDEBUG   [0m selenium.webdriver.remote.remote_connection:remote_connection.py:403 DELETE http://localhost:52544/session/43ca733a003044f6e3ca34ad10d9396d {}
[35mDEBUG   [0m urllib3.connectionpool:connectionpool.py:241 Starting new HTTP connection (2): localhost:52544
[35mDEBUG   [0m urllib3.util.retry:retry.py:521 Incremented Retry for (url='/session/43ca733a003044f6e3ca34ad10d9396d'): Retry(total=2, connect=None, read=None, redirect=None, status=None)
[33mWARNING [0m urllib3.connectionpool:connectionpool.py:868 Retrying (Retry(total=2, connect=None, read=None, redirect=None, status=None)) after connection broken by 'NewConnectionError('<urllib3.connection.HTTPConnection object at 0x1049ba2e0>: Failed to establish a new connection: [Errno 61] Connection refused')': /session/43ca733a003044f6e3ca34ad10d9396d
[35mDEBUG   [0m urllib3.connectionpool:connectionpool.py:241 Starting new HTTP connection (3): localhost:52544
[35mDEBUG   [0m urllib3.util.retry:retry.py:521 Incremented Retry for (url='/session/43ca733a003044f6e3ca34ad10d9396d'): Retry(total=1, connect=None, read=None, redirect=None, status=None)
[33mWARNING [0m urllib3.connectionpool:connectionpool.py:868 Retrying (Retry(total=1, connect=None, read=None, redirect=None, status=None)) after connection broken by 'NewConnectionError('<urllib3.connection.HTTPConnection object at 0x1049ba760>: Failed to establish a new connection: [Errno 61] Connection refused')': /session/43ca733a003044f6e3ca34ad10d9396d
[35mDEBUG   [0m urllib3.connectionpool:connectionpool.py:241 Starting new HTTP connection (4): localhost:52544
[35mDEBUG   [0m urllib3.util.retry:retry.py:521 Incremented Retry for (url='/session/43ca733a003044f6e3ca34ad10d9396d'): Retry(total=0, connect=None, read=None, redirect=None, status=None)
[33mWARNING [0m urllib3.connectionpool:connectionpool.py:868 Retrying (Retry(total=0, connect=None, read=None, redirect=None, status=None)) after connection broken by 'NewConnectionError('<urllib3.connection.HTTPConnection object at 0x1049baf40>: Failed to establish a new connection: [Errno 61] Connection refused')': /session/43ca733a003044f6e3ca34ad10d9396d
[35mDEBUG   [0m urllib3.connectionpool:connectionpool.py:241 Starting new HTTP connection (5): localhost:52544